<?xml version="1.0" ?>

<robot name="my_rb1_robot">
    <gazebo reference="base_link">
        <material>Gazebo/Black</material>
    </gazebo>
    <gazebo reference="back_caster">
        <material>Gazebo/Black</material>
    </gazebo>
    <gazebo reference="front_caster">
        <material>Gazebo/Black</material>
    </gazebo>
    <gazebo reference="right_wheel">
        <material>Gazebo/Black</material>
    </gazebo>
    <gazebo reference="left_wheel">
        <material>Gazebo/Black</material>
    </gazebo>
    <gazebo reference="front_laser">
        <material>Gazebo/Black</material>
    </gazebo>
    <!-- Link - base_link -->
    <link name="base_link">
        <inertial>
            <mass value="22.5" />
            <origin xyz="0 0 0.15" rpy="0 0 0" />
            <inertia ixx="0.5203" ixy="0" ixz="0" iyy="0.5203" iyz="0" izz="0.7031" />
        </inertial>

        <collision>
            <geometry>
                <cylinder length="0.30" radius="0.25"/>
            </geometry>
        </collision>

        <visual>
            <geometry>
                <cylinder length="0.30" radius="0.25"/>
            </geometry>
            <material name="DarkBlue">
                <color rgba="0.2 0.2 0.4 1" />
            </material>
        </visual>
    </link>

    <!-- Joint - base/base_footprint-->
    <joint name="joint_base_base_footprint" type="fixed">
        <origin rpy="0 0 0" xyz="0 0 -0.15" />
        <child link="base_footprint" />
        <parent link="base_link" />
        <joint_properties damping="1.0" friction="1.0" />
    </joint>
    
    
    <!-- Link - base_footprint -->
    <link name="base_footprint">
        <origin xyz="0 0 0" rpy="0 0 0" />
    </link>

    <!-- Joint - base/right wheel -->
    <joint name="joint_base_right_wheel" type="continuous">
        <origin rpy="0 0 0" xyz="0 -0.2 -0.15" />
        <child link="right_wheel" />
        <parent link="base_link" />
        <axis rpy="0 0 0" xyz="0 1 0" />
        <limit effort="10000" velocity="1000" />
        <joint_properties damping="1.0" friction="1.0" />
    </joint>

    <!-- Link - right wheel -->
    <link name="right_wheel">
        <inertial>
            <mass value="0.5" />
            <origin xyz="0 0 0" rpy="0 0 0" />
            <inertia ixx="0.00011563" ixy="0" ixz="0" iyy="0.00011563" iyz="0" izz="0.00015625"/>
        </inertial>

        <collision>
            <origin rpy="1.5707 0 0" xyz="0 -0.015 0" />
            <geometry>
                <cylinder length="0.03" radius="0.025"/>
            </geometry>
        </collision>

        <visual>
            <origin rpy="1.5707 0 0" xyz="0 -0.015 0" />
            <geometry>
                <cylinder length="0.03" radius="0.025"/>
            </geometry>
            <material name="Red">
                <color rgba="0.7 0.1 0.1 1" />
            </material>
        </visual>
    </link>


    <!-- Joint - base/left wheel -->
    <joint name="joint_base_left_wheel" type="continuous">
        <origin rpy="0 0 0" xyz="0 0.2 -0.15" />
        <child link="left_wheel" />
        <parent link="base_link" />
        <axis rpy="0 0 0" xyz="0 1 0" />
        <limit effort="10000" velocity="1000" />
        <joint_properties damping="1.0" friction="1.0" />
    </joint>


    <!-- Link - left wheel -->
    <link name="left_wheel">
        <inertial>
            <mass value="0.5" />
            <origin xyz="0 0 0" rpy="0 0 0" />
            <inertia ixx="0.00011563" ixy="0" ixz="0" iyy="0.00011563" iyz="0" izz="0.00015625"/>
        </inertial>

        <collision>
            <origin rpy="1.5707 0 0" xyz="0 0.015 0" />
            <geometry>
                <cylinder length="0.03" radius="0.025"/>
            </geometry>
            <material name="Red">
                <color rgba="0.7 0.1 0.1 1" />
            </material>
        </collision>

        <visual>
            <origin rpy="1.5707 0 0" xyz="0 0.015 0" />
            <geometry>
                <cylinder length="0.03" radius="0.025"/>
            </geometry>
        </visual>
    </link>


    <!-- Joint - caster wheel back -->
    <joint name="joint_base_caster_wheel_back" type="fixed">
        <origin rpy="0 0 0" xyz="-0.1 0.0 -0.15" />
        <child link="back_caster" />
        <parent link="base_link" />
        <joint_properties damping="1.0" friction="1" />
    </joint>
    
    <!-- Link - caster wheel back -->
    <link name="back_caster">
        <inertial>
            <mass value="0.5" />
            <origin xyz="0 0 0" rpy="0 0 0" />
            <inertia ixx="0.00020833" ixy="0" ixz="0" iyy="0.00020833" iyz="0" izz="0.00020833"/>
        </inertial>
        
        <collision>
            <origin rpy="0 0 0" xyz="0 0 0" />
            <geometry>
                <sphere radius="0.025" />
            </geometry>
        </collision>
        
        <visual>
            <origin rpy="0 0 0" xyz="0 0 0" />
            <geometry>
                <sphere radius="0.025" />
            </geometry>
            <material name="Grey">
                <color rgba="0.6 0.6 0.6 1" />
            </material>
        </visual>
    </link>


    <!-- Joint - caster wheel front -->
    <joint name="joint_base_caster_wheel_front" type="fixed">
        <origin rpy="0 0 0" xyz="0.1 0.0 -0.15" />
        <child link="front_caster" />
        <parent link="base_link" />
        <joint_properties damping="1.0" friction="1" />
    </joint>
    

    <!-- Link - caster wheel front -->
    <link name="front_caster">
        <inertial>
            <mass value="0.5" />
            <origin xyz="0 0 0" rpy="0 0 0" />
            <inertia ixx="0.00020833" ixy="0" ixz="0" iyy="0.00020833" iyz="0" izz="0.00020833"/>
        </inertial>

        <collision>
            <origin rpy="0 0 0" xyz="0 0 0" />
            <geometry>
                <sphere radius="0.025" />
            </geometry>
        </collision>

        <visual>
            <origin rpy="0 0 0" xyz="0 0 0" />
            <geometry>
                <sphere radius="0.025" />
            </geometry>
            <material name="Grey">
                <color rgba="0.6 0.6 0.6 1" />
            </material>
        </visual>
    </link>


    <!-- Joint front_laser/base -->
    <joint name="joint_front_laser_base" type="fixed">
        <origin rpy="3.14159 0 0" xyz="0.25 0 0.075" />
        <child link="front_laser" />
        <parent link="base_link" />
        <joint_properties damping="1.0" friction="1.0" />
    </joint>


    <!-- Link front_laser -->
    <link name="front_laser">
        <inertial>
            <origin xyz="0 0 0" rpy="0 0 0" />
            <mass value="0.5" />
            <inertia ixx="0.0004167" ixy="0" ixz="0" iyy="0.0004167" iyz="0" izz="0.000625"/>
        </inertial>

        <collision>
            <origin xyz="0 0 0" rpy="0 0 0"/>
            <geometry>
                <cylinder radius="0.05" length="0.05"/>
            </geometry>
        </collision>
        
        <visual>
            <origin xyz="0 0 0" rpy="0 0 0" />
            <geometry>
                <cylinder radius="0.05" length="0.05"/>
            </geometry>
            <material name="Red">
                <color rgba="0.7 0.1 0.1 1" />
            </material>
        </visual>
    </link>
</robot>